<?xml version="1.0" ?>
<robot name="twoR_lab2">
  <link name="twoR_link1">
    <inertial>
      <mass value="1.0"/>
    </inertial>
    <visual>
      <geometry>
        <box size="0.4 0.05 0.05"/>
      </geometry>
    </visual>
  </link>
  <link name="twoR_link2">
    <inertial>
      <mass value="1.0"/>
    </inertial>
    <visual>
      <geometry>
        <box size="0.25 0.05 0.05"/>
      </geometry>
    </visual>
  </link>
  <link name="twoR_ee">
    <inertial>
      <mass value="1.0"/>
    </inertial>
  </link>
  <joint name="twoR_joint1" type="revolute">
    <parent link="world"/>
    <child link="twoR_link1"/>
    <origin xyz="0 0 0" rpy="0 0 0"/>
    <axis xyz="0 0 1"/>
  </joint>
  <joint name="twoR_joint2" type="revolute">
    <parent link="twoR_link1"/>
    <child link="twoR_link2"/>
    <origin xyz="0.4 0 0" rpy="0 0 0"/>
    <axis xyz="0 0 1"/>
  </joint>
  <joint name="twoR_joint_ee" type="fixed">
    <parent link="twoR_link2"/>
    <child link="twoR_ee"/>
    <origin xyz="0.25 0 0" rpy="0 0 0"/>
  </joint>
</robot>
